<robot name="rover">
  <!-- Links --> 
  <link name="base_footprint" />

  <link name="robot_base">
    <visual>
      <geometry>
        <box size="0.205 0.13 0.065" />
      </geometry>
      <material name="blue">
        <color rgba="0 0 0.75 1.0" />
      </material>
    </visual>
    <collision>
      <geometry>
        <box size="0.205 0.13 0.065" />
      </geometry>
    </collision>
  </link>

  <link name="robot_base_crossbar">
    <visual>
      <geometry>
        <box size="0.085 0.21 0.065" />
      </geometry>
      <material name="blue">
        <color rgba="0 0 0.75 1.0" />
      </material>
    </visual>
    <collision>
      <geometry>
        <box size="0.085 0.21 0.065" />
      </geometry>
    </collision>
  </link>

  <link name="robot_base_plate">
    <visual>
      <geometry>
        <box size="0.2051 0.211 0.015" />
      </geometry>
      <material name="yellow">
        <color rgba="0.75 0.75 0 1.0" />
      </material>
    </visual>
    <collision>
      <geometry>
        <box size="0.2051 0.211 0.015" />
      </geometry>
    </collision>
  </link>

  <link name="robot_base_standoff">
    <visual>
      <geometry>
        <box size="0.095 0.135 0.025" />
      </geometry>
      <material name="red-green">
        <color rgba="1 1 0 1.0" />
      </material>
    </visual>
    <collision>
      <geometry>
        <box size="0.095 0.135 0.025" />
      </geometry>
    </collision>
  </link>

  <link name="front_left_wheel">
    <visual>
      <geometry>
        <cylinder radius="0.027051" length="0.0531" />
      </geometry>
      <material name="dark_gray">
        <color rgba="0.3 0.3 0.3 1.0" />
      </material>
    </visual>
    <collision>
      <geometry>
        <cylinder radius="0.027051" length="0.0531" />
      </geometry>
    </collision>
  </link>

  <link name="front_right_wheel">
    <visual>
      <geometry>
        <cylinder radius="0.027051" length="0.0531" />
      </geometry>
      <material name="dark_gray">
        <color rgba="0.3 0.3 0.3 1.0" />
      </material>
    </visual>
    <collision>
      <geometry>
        <cylinder radius="0.027051" length="0.0531" />
      </geometry>
    </collision>
  </link>

  <link name="back_left_wheel">
    <visual>
      <geometry>
        <cylinder radius="0.027051" length="0.0531" />
      </geometry>
      <material name="dark_gray">
        <color rgba="0.3 0.3 0.3 1.0" />
      </material>
    </visual>
    <collision>
      <geometry>
        <cylinder radius="0.027051" length="0.0531" />
      </geometry>
    </collision>
  </link>

  <link name="back_right_wheel">
    <visual>
      <geometry>
        <cylinder radius="0.027051" length="0.0531" />
      </geometry>
      <material name="dark_gray">
        <color rgba="0.3 0.3 0.3 1.0" />
      </material>
    </visual>
    <collision>
      <geometry>
        <cylinder radius="0.027051" length="0.0531" />
      </geometry>
    </collision>
  </link>

 <link name="laptop_link">
    <visual>
      <geometry>
        <box size="0.3075 0.35 0.0475" />
      </geometry>
      <material name="darkish_green">
        <color rgba="0 0.75 0.1 1.0" />
      </material>
    </visual>
    <collision>
      <geometry>
        <box size="0.3075 0.35 0.0475" />
      </geometry>
    </collision>
  </link>


  <link name="kinect_stand_base">
    <visual>
      <geometry>
        <box size="0.075 0.35 0.04" />
      </geometry>
      <material name="blue">
        <color rgba="0 0 0.3 1.0" />
      </material>
    </visual>
    <collision>
      <geometry>
        <box size="0.075 0.35 0.04" />
      </geometry>
    </collision>
  </link>

  <link name="pan_servo">
    <visual>
      <geometry>
        <box size="0.04 0.02 0.035" />
      </geometry>
      <material name="yellow">
        <color rgba="0.9 0.9 0.5 1.0" />
      </material>
    </visual>
    <collision>
      <geometry>
        <box size="0.04 0.02 0.035" />
      </geometry>
    </collision>
  </link>

  <link name="tilt_servo">
    <visual>
      <geometry>
        <box size="0.05 0.035 0.04" />
      </geometry>
      <material name="dark_purple">
        <color rgba="0.3 0 0.3 1.0" />
      </material>
    </visual>
    <collision>
      <geometry>
        <box size="0.05 0.035 0.04" />
      </geometry>
    </collision>
  </link>

  <link name="camera_body">
    <visual>
      <geometry>
	<cylinder radius="0.0125" length="0.055" />
      </geometry>
      <material name="magenta">
        <color rgba="1 0 1 1.0" />
      </material>
    </visual>
    <collision>
      <geometry>
        <cylinder radius="0.0125" length="0.055" />
      </geometry>
    </collision>
  </link>

  <link name="camera" />

  <link name="kinect_stand">
    <visual>
      <geometry>
        <box size="0.045 0.055 0.305" />
      </geometry>
      <material name="dark_green">
        <color rgba="0 0.7 0 1.0" />
      </material>
    </visual>
    <collision>
      <geometry>
        <box size="0.045 0.055 0.305" />
      </geometry>
    </collision>
  </link>

  <link name="kinect_base">
    <visual>
      <geometry>
        <box size="0.06 0.075 0.03" />
      </geometry>
      <material name="purple">
        <color rgba="0.3 0 0.3 0.5" />
      </material>
    </visual>
    <collision>
      <geometry>
        <box size="0.06 0.075 0.03" />
      </geometry>
    </collision>
  </link>

  <link name="openni_camera">
    <visual>
      <geometry>
        <box size="0.06 0.285 0.035" />
      </geometry>
      <material name="magenta">
        <color rgba="1 0 1 1.0" />
      </material>
    </visual>
    <collision>
      <geometry>
        <box size="0.06 0.285 0.035" />
      </geometry>
    </collision>
  </link>

  <!-- Joints -->

  <joint name="base_joint" type="fixed">
    <parent link="base_footprint" />
    <child link="robot_base" />
    <origin xyz="0 0 0.0335" rpy="0 0 0" />
    <axis xyz="0 1 0" />
  </joint>

  <joint name="crossbar_joint" type="fixed">
    <parent link="robot_base" />
    <child link="robot_base_crossbar" />
    <origin xyz="0 0 0" rpy="0 0 0" />
    <axis xyz="0 1 0" />
  </joint>

  <joint name="plate_joint" type="fixed">
    <parent link="robot_base" />
    <child link="robot_base_plate" />
    <origin xyz="0 0 0.02575" rpy="0 0 0" />
    <axis xyz="0 1 0" />
  </joint>

  <joint name="standoff_joint" type="fixed">
    <parent link="robot_base" />
    <child link="robot_base_standoff" />
    <origin xyz="0 0 0.045" rpy="0 0 0" />
    <axis xyz="0 1 0" />
  </joint>

  <joint name="front_left_wheel_joint" type="continuous">
    <parent link="robot_base" />
    <child link="front_left_wheel" />
    <origin xyz="0.07 0.085 -0.01" rpy="-1.57079633 0 0" />
    <axis xyz="0 1 0" />
    <limit effort="1000.0" velocity="10.0"/>
  </joint>

  <joint name="front_right_wheel_joint" type="continuous">
    <parent link="robot_base" />
    <child link="front_right_wheel" />
    <origin xyz="0.07 -0.085 -0.01" rpy="1.57079633 0 0" />
    <axis xyz="0 1 0" />
    <limit effort="1000.0" velocity="10.0"/>
  </joint>

  <joint name="back_left_wheel_joint" type="continuous">
    <parent link="robot_base" />
    <child link="back_left_wheel" />
    <origin xyz="-0.07 0.085 -0.01" rpy="-1.57079633 0 0" />
    <axis xyz="0 1 0" />
    <limit effort="1000.0" velocity="10.0"/>
  </joint>

  <joint name="back_right_wheel_joint" type="continuous">
    <parent link="robot_base" />
    <child link="back_right_wheel" />
    <origin xyz="-0.07 -0.085 -0.01" rpy="1.57079633 0 0" />
    <axis xyz="0 1 0" />
    <limit effort="1000.0" velocity="10.0"/>
  </joint>

  <joint name="laptop_joint" type="fixed">
    <parent link="robot_base_standoff" />
    <child link="laptop_link" />
    <origin xyz="0 0 0.03625" rpy="0 0 0" />
    <axis xyz="0 1 0" />
  </joint>

  <joint name="stand_base_joint" type="fixed">
    <parent link="laptop_link" />
    <child link="kinect_stand_base" />
    <origin xyz="-0.11625 0 0.04375" rpy="0 0 0" />
    <axis xyz="0 1 0" />
  </joint>

  <joint name="pan_servo_base" type="fixed">
    <parent link="kinect_stand_base" />
    <child link="pan_servo" />
    <origin xyz="0.0575 0 0.015" rpy="0 0 0" />
    <axis xyz="0 1 0" />
  </joint>

  <joint name="pan_servo_joint" type="revolute">
    <parent link="pan_servo" />
    <child link="tilt_servo" />
    <origin xyz="0.02 0 0.0375" rpy="0 0 0" />
    <axis xyz="0 0 1" />
    <limit effort="1000.0" velocity="1.0" lower="-1.57079633" upper="1.57079633" />
  </joint>

  <joint name="tilt_servo_joint" type="revolute">
    <parent link="tilt_servo" />
    <child link="camera_body" />
    <origin xyz="0.025 -0.02375 0.01" rpy="0 1.57079633 0" />
    <axis xyz="0 1 0" />
    <limit effort="1000.0" velocity="1.0" lower="-1.57079633" upper="1.57079633" />
  </joint>

  <joint name="camera_joint" type="fixed">
    <parent link="camera_body" />
    <child link="camera" />
    <origin xyz="0 0 0.03" rpy="0 0 -1.57079633"/>
    <axis xyz="0 1 0" />
  </joint>

  <joint name="stand_joint" type="fixed">
    <parent link="kinect_stand_base" />
    <child link="kinect_stand" />
    <origin xyz="-0.01 0.01 0.1725" rpy="0 0 0" />
    <axis xyz="0 1 0" />
  </joint>

  <joint name="kinect_base_joint" type="fixed">
    <parent link="kinect_stand" />
    <child link="kinect_base" />
    <origin xyz="0 0 0.1675" rpy="0 0 0" />
    <axis xyz="0 1 0" />
  </joint>

  <joint name="kinect_joint" type="revolute">
    <parent link="kinect_base" />
    <child link="openni_camera" />
    <origin xyz="0 0 0.0375" rpy="0 0 0" />
    <axis xyz="0 1 0" />
    <limit effort="1000.0" lower="-0.523598776" upper="0.523598776" velocity="0.5" />
  </joint>

</robot>
